Workbook

Sheet OFT
H3: OFT | I3: OFT | J3: OFT | K3: DAR | L3: DAR | M3: DAR | N3: ETS | O3: ETS | P3: ETS | Q3: Wharfage | R3: Wharfage | S3: Wharfage | T3: All-in | U3: All-in | V3: All-in | AA3: OLD | AD3: DIFFERENCE
A4: CY-CY REF | B4: DAR REF | C4: Origin Country | D4: POR | E4: POL | F4: POD | G4: Destination | H4: 20' | I4: 40' | J4: 40HC | K4: 20' | L4: 40' | M4: 40HC | N4: 20' | O4: 40' | P4: 40HC | Q4: 20' | R4: 40' | S4: 40HC | T4: 20' | U4: 40' | V4: 40HC | W4: Valid from | X4: Valid to | Y4: Remark | AA4: 20' | AB4: 40' | AC4: 40HC | AD4: 20' | AE4: 40' | AF4: 40HC
A5: =E5&F5 | C5: =VLOOKUP(D5,Sheet1!$A$1:$B$4,2,FALSE) | D5: BREMERHAVEN | E5: BREMERHAVEN | F5: NEW YORK, NY | G5: NEW YORK, NY | H5: 1750 | I5: 1850 | J5: 1850 | T5: =SUM(H5,K5,N5,Q5) | U5: =SUM(I5,L5,O5,R5) | V5: =SUM(J5,M5,P5,S5) | W5: 46082 | X5: 46112 | AA5: 46082 | AB5: 46112 | AD5: =T5-AA5 | AE5: =U5-AB5 | AF5: =V5-AC5
A6: =E6&F6 | C6: =VLOOKUP(D6,Sheet1!$A$1:$B$4,2,FALSE) | D6: BREMERHAVEN | E6: BREMERHAVEN | F6: BALTIMORE, MD | G6: BALTIMORE, MD | H6: 1750 | I6: 1850 | J6: 1850 | T6: =SUM(H6,K6,N6,Q6) | U6: =SUM(I6,L6,O6,R6) | V6: =SUM(J6,M6,P6,S6) | W6: 46082 | X6: 46112 | AA6: 46082 | AB6: 46112 | AD6: =T6-AA6 | AE6: =U6-AB6 | AF6: =V6-AC6
A7: =E7&F7 | C7: =VLOOKUP(D7,Sheet1!$A$1:$B$4,2,FALSE) | D7: BREMERHAVEN | E7: BREMERHAVEN | F7: NORFOLK, VA | G7: NORFOLK, VA | H7: 1750 | I7: 1850 | J7: 1850 | T7: =SUM(H7,K7,N7,Q7) | U7: =SUM(I7,L7,O7,R7) | V7: =SUM(J7,M7,P7,S7) | W7: 46082 | X7: 46112 | AA7: 46082 | AB7: 46112 | AD7: =T7-AA7 | AE7: =U7-AB7 | AF7: =V7-AC7
A8: =E8&F8 | C8: =VLOOKUP(D8,Sheet1!$A$1:$B$4,2,FALSE) | D8: BREMERHAVEN | E8: BREMERHAVEN | F8: HOUSTON, TX | G8: HOUSTON, TX | H8: 1750 | I8: 1850 | J8: 1850 | Q8: 80.49 | R8: 80.49 | S8: 80.49 | T8: =SUM(H8,K8,N8,Q8) | U8: =SUM(I8,L8,O8,R8) | V8: =SUM(J8,M8,P8,S8) | W8: 46082 | X8: 46112 | AA8: 46082 | AB8: 46112 | AD8: =T8-AA8 | AE8: =U8-AB8 | AF8: =V8-AC8
A9: =E9&F9 | C9: =VLOOKUP(D9,Sheet1!$A$1:$B$4,2,FALSE) | D9: BREMERHAVEN | E9: BREMERHAVEN | F9: NEW ORLEANS, LA | G9: NEW ORLEANS, LA | H9: 1750 | I9: 1850 | J9: 1850 | Q9: 68 | R9: 68 | S9: 68 | T9: =SUM(H9,K9,N9,Q9) | U9: =SUM(I9,L9,O9,R9) | V9: =SUM(J9,M9,P9,S9) | W9: 46082 | X9: 46112 | AA9: 46082 | AB9: 46112 | AD9: =T9-AA9 | AE9: =U9-AB9 | AF9: =V9-AC9
A10: =E10&F10 | C10: =VLOOKUP(D10,Sheet1!$A$1:$B$4,2,FALSE) | D10: BREMERHAVEN | E10: BREMERHAVEN | F10: SAVANNAH, GA | G10: SAVANNAH, GA | H10: 1350 | I10: 1550 | J10: 1550 | T10: =SUM(H10,K10,N10,Q10) | U10: =SUM(I10,L10,O10,R10) | V10: =SUM(J10,M10,P10,S10) | W10: 46082 | X10: 46112 | AA10: 46082 | AB10: 46112 | AD10: =T10-AA10 | AE10: =U10-AB10 | AF10: =V10-AC10
A11: =E11&F11 | C11: =VLOOKUP(D11,Sheet1!$A$1:$B$4,2,FALSE) | D11: BREMERHAVEN | E11: BREMERHAVEN | F11: CHARLESTON, SC | G11: CHARLESTON, SC | H11: 1350 | I11: 1550 | J11: 1550 | T11: =SUM(H11,K11,N11,Q11) | U11: =SUM(I11,L11,O11,R11) | V11: =SUM(J11,M11,P11,S11) | W11: 46082 | X11: 46112 | AA11: 46082 | AB11: 46112 | AD11: =T11-AA11 | AE11: =U11-AB11 | AF11: =V11-AC11
A12: =E12&F12 | C12: =VLOOKUP(D12,Sheet1!$A$1:$B$4,2,FALSE) | D12: ROTTERDAM | E12: ROTTERDAM | F12: NEW YORK, NY | G12: NEW YORK, NY | H12: =H5 | I12: =I5 | J12: =J5 | T12: =SUM(H12,K12,N12,Q12) | U12: =SUM(I12,L12,O12,R12) | V12: =SUM(J12,M12,P12,S12) | W12: 46082 | X12: 46112 | AA12: 46082 | AB12: 46112 | AD12: =T12-AA12 | AE12: =U12-AB12 | AF12: =V12-AC12
A13: =E13&F13 | C13: =VLOOKUP(D13,Sheet1!$A$1:$B$4,2,FALSE) | D13: ROTTERDAM | E13: ROTTERDAM | F13: BALTIMORE, MD | G13: BALTIMORE, MD | H13: =H6 | I13: =I6 | J13: =J6 | T13: =SUM(H13,K13,N13,Q13) | U13: =SUM(I13,L13,O13,R13) | V13: =SUM(J13,M13,P13,S13) | W13: 46082 | X13: 46112 | AA13: 46082 | AB13: 46112 | AD13: =T13-AA13 | AE13: =U13-AB13 | AF13: =V13-AC13
A14: =E14&F14 | C14: =VLOOKUP(D14,Sheet1!$A$1:$B$4,2,FALSE) | D14: ROTTERDAM | E14: ROTTERDAM | F14: NORFOLK, VA | G14: NORFOLK, VA | H14: =H7 | I14: =I7 | J14: =J7 | T14: =SUM(H14,K14,N14,Q14) | U14: =SUM(I14,L14,O14,R14) | V14: =SUM(J14,M14,P14,S14) | W14: 46082 | X14: 46112 | AA14: 46082 | AB14: 46112 | AD14: =T14-AA14 | AE14: =U14-AB14 | AF14: =V14-AC14
A15: =E15&F15 | C15: =VLOOKUP(D15,Sheet1!$A$1:$B$4,2,FALSE) | D15: ROTTERDAM | E15: ROTTERDAM | F15: HOUSTON, TX | G15: HOUSTON, TX | H15: =H8 | I15: =I8 | J15: =J8 | Q15: 80.49 | R15: 80.49 | S15: 80.49 | T15: =SUM(H15,K15,N15,Q15) | U15: =SUM(I15,L15,O15,R15) | V15: =SUM(J15,M15,P15,S15) | W15: 46082 | X15: 46112 | AA15: 46082 | AB15: 46112 | AD15: =T15-AA15 | AE15: =U15-AB15 | AF15: =V15-AC15
A16: =E16&F16 | C16: =VLOOKUP(D16,Sheet1!$A$1:$B$4,2,FALSE) | D16: ROTTERDAM | E16: ROTTERDAM | F16: NEW ORLEANS, LA | G16: NEW ORLEANS, LA | H16: =H9 | I16: =I9 | J16: =J9 | Q16: 68 | R16: 68 | S16: 68 | T16: =SUM(H16,K16,N16,Q16) | U16: =SUM(I16,L16,O16,R16) | V16: =SUM(J16,M16,P16,S16) | W16: 46082 | X16: 46112 | AA16: 46082 | AB16: 46112 | AD16: =T16-AA16 | AE16: =U16-AB16 | AF16: =V16-AC16
A17: =E17&F17 | C17: =VLOOKUP(D17,Sheet1!$A$1:$B$4,2,FALSE) | D17: ROTTERDAM | E17: ROTTERDAM | F17: SAVANNAH, GA | G17: SAVANNAH, GA | H17: =H10 | I17: =I10 | J17: =J10 | T17: =SUM(H17,K17,N17,Q17) | U17: =SUM(I17,L17,O17,R17) | V17: =SUM(J17,M17,P17,S17) | W17: 46082 | X17: 46112 | AA17: 46082 | AB17: 46112 | AD17: =T17-AA17 | AE17: =U17-AB17 | AF17: =V17-AC17
A18: =E18&F18 | C18: =VLOOKUP(D18,Sheet1!$A$1:$B$4,2,FALSE) | D18: ROTTERDAM | E18: ROTTERDAM | F18: CHARLESTON, SC | G18: CHARLESTON, SC | H18: =H11 | I18: =I11 | J18: =J11 | T18: =SUM(H18,K18,N18,Q18) | U18: =SUM(I18,L18,O18,R18) | V18: =SUM(J18,M18,P18,S18) | W18: 46082 | X18: 46112 | AA18: 46082 | AB18: 46112 | AD18: =T18-AA18 | AE18: =U18-AB18 | AF18: =V18-AC18
A19: =E19&F19 | C19: =VLOOKUP(D19,Sheet1!$A$1:$B$4,2,FALSE) | D19: ANTWERP | E19: ANTWERP | F19: NEW YORK, NY | G19: NEW YORK, NY | H19: =H5 | I19: =I5 | J19: =J5 | T19: =SUM(H19,K19,N19,Q19) | U19: =SUM(I19,L19,O19,R19) | V19: =SUM(J19,M19,P19,S19) | W19: 46082 | X19: 46112 | AA19: 46082 | AB19: 46112 | AD19: =T19-AA19 | AE19: =U19-AB19 | AF19: =V19-AC19
A20: =E20&F20 | C20: =VLOOKUP(D20,Sheet1!$A$1:$B$4,2,FALSE) | D20: ANTWERP | E20: ANTWERP | F20: BALTIMORE, MD | G20: BALTIMORE, MD | H20: =H6 | I20: =I6 | J20: =J6 | T20: =SUM(H20,K20,N20,Q20) | U20: =SUM(I20,L20,O20,R20) | V20: =SUM(J20,M20,P20,S20) | W20: 46082 | X20: 46112 | AA20: 46082 | AB20: 46112 | AD20: =T20-AA20 | AE20: =U20-AB20 | AF20: =V20-AC20
A21: =E21&F21 | C21: =VLOOKUP(D21,Sheet1!$A$1:$B$4,2,FALSE) | D21: ANTWERP | E21: ANTWERP | F21: NORFOLK, VA | G21: NORFOLK, VA | H21: =H7 | I21: =I7 | J21: =J7 | T21: =SUM(H21,K21,N21,Q21) | U21: =SUM(I21,L21,O21,R21) | V21: =SUM(J21,M21,P21,S21) | W21: 46082 | X21: 46112 | AA21: 46082 | AB21: 46112 | AD21: =T21-AA21 | AE21: =U21-AB21 | AF21: =V21-AC21
A22: =E22&F22 | C22: =VLOOKUP(D22,Sheet1!$A$1:$B$4,2,FALSE) | D22: ANTWERP | E22: ANTWERP | F22: HOUSTON, TX | G22: HOUSTON, TX | H22: =H8 | I22: =I8 | J22: =J8 | Q22: 80.49 | R22: 80.49 | S22: 80.49 | T22: =SUM(H22,K22,N22,Q22) | U22: =SUM(I22,L22,O22,R22) | V22: =SUM(J22,M22,P22,S22) | W22: 46082 | X22: 46112 | AA22: 46082 | AB22: 46112 | AD22: =T22-AA22 | AE22: =U22-AB22 | AF22: =V22-AC22
A23: =E23&F23 | C23: =VLOOKUP(D23,Sheet1!$A$1:$B$4,2,FALSE) | D23: ANTWERP | E23: ANTWERP | F23: NEW ORLEANS, LA | G23: NEW ORLEANS, LA | H23: =H9 | I23: =I9 | J23: =J9 | Q23: 68 | R23: 68 | S23: 68 | T23: =SUM(H23,K23,N23,Q23) | U23: =SUM(I23,L23,O23,R23) | V23: =SUM(J23,M23,P23,S23) | W23: 46082 | X23: 46112 | AA23: 46082 | AB23: 46112 | AD23: =T23-AA23 | AE23: =U23-AB23 | AF23: =V23-AC23
A24: =E24&F24 | C24: =VLOOKUP(D24,Sheet1!$A$1:$B$4,2,FALSE) | D24: ANTWERP | E24: ANTWERP | F24: SAVANNAH, GA | G24: SAVANNAH, GA | H24: =H10 | I24: =I10 | J24: =J10 | T24: =SUM(H24,K24,N24,Q24) | U24: =SUM(I24,L24,O24,R24) | V24: =SUM(J24,M24,P24,S24) | W24: 46082 | X24: 46112 | AA24: 46082 | AB24: 46112 | AD24: =T24-AA24 | AE24: =U24-AB24 | AF24: =V24-AC24
A25: =E25&F25 | C25: =VLOOKUP(D25,Sheet1!$A$1:$B$4,2,FALSE) | D25: ANTWERP | E25: ANTWERP | F25: CHARLESTON, SC | G25: CHARLESTON, SC | H25: =H11 | I25: =I11 | J25: =J11 | T25: =SUM(H25,K25,N25,Q25) | U25: =SUM(I25,L25,O25,R25) | V25: =SUM(J25,M25,P25,S25) | W25: 46082 | X25: 46112 | AA25: 46082 | AB25: 46112 | AD25: =T25-AA25 | AE25: =U25-AB25 | AF25: =V25-AC25
A26: =E26&F26 | C26: =VLOOKUP(D26,Sheet1!$A$1:$B$4,2,FALSE) | D26: HAMBURG | E26: HAMBURG | F26: MIAMI, FL | G26: MIAMI, FL | H26: 2100 | I26: 2500 | J26: 2500 | Q26: 37 | R26: 75 | S26: 75 | T26: =SUM(H26,K26,N26,Q26) | U26: =SUM(I26,L26,O26,R26) | V26: =SUM(J26,M26,P26,S26) | W26: 46082 | X26: 46112 | AA26: 46082 | AB26: 46112 | AD26: =T26-AA26 | AE26: =U26-AB26 | AF26: =V26-AC26
A27: =E27&F27 | C27: =VLOOKUP(D27,Sheet1!$A$1:$B$4,2,FALSE) | D27: HAMBURG | E27: HAMBURG | F27: OAKLAND, CA | G27: OAKLAND, CA | H27: 2100 | I27: 2500 | J27: 2500 | T27: =SUM(H27,K27,N27,Q27) | U27: =SUM(I27,L27,O27,R27) | V27: =SUM(J27,M27,P27,S27) | W27: 46082 | X27: 46112 | AA27: 46082 | AB27: 46112 | AD27: =T27-AA27 | AE27: =U27-AB27 | AF27: =V27-AC27
A28: =E28&F28 | C28: =VLOOKUP(D28,Sheet1!$A$1:$B$4,2,FALSE) | D28: HAMBURG | E28: HAMBURG | F28: LONG BEACH, CA | G28: LONG BEACH, CA | H28: 2100 | I28: 2500 | J28: 2500 | T28: =SUM(H28,K28,N28,Q28) | U28: =SUM(I28,L28,O28,R28) | V28: =SUM(J28,M28,P28,S28) | W28: 46082 | X28: 46112 | AA28: 46082 | AB28: 46112 | AD28: =T28-AA28 | AE28: =U28-AB28 | AF28: =V28-AC28
A29: =E29&F29 | C29: =VLOOKUP(D29,Sheet1!$A$1:$B$4,2,FALSE) | D29: ROTTERDAM | E29: ROTTERDAM | F29: MIAMI, FL | G29: MIAMI, FL | H29: =H26 | I29: =I26 | J29: =J26 | Q29: 37 | R29: 75 | S29: 75 | T29: =SUM(H29,K29,N29,Q29) | U29: =SUM(I29,L29,O29,R29) | V29: =SUM(J29,M29,P29,S29) | W29: 46082 | X29: 46112 | AA29: 46082 | AB29: 46112 | AD29: =T29-AA29 | AE29: =U29-AB29 | AF29: =V29-AC29
A30: =E30&F30 | C30: =VLOOKUP(D30,Sheet1!$A$1:$B$4,2,FALSE) | D30: ROTTERDAM | E30: ROTTERDAM | F30: OAKLAND, CA | G30: OAKLAND, CA | H30: =H27 | I30: =I27 | J30: =J27 | T30: =SUM(H30,K30,N30,Q30) | U30: =SUM(I30,L30,O30,R30) | V30: =SUM(J30,M30,P30,S30) | W30: 46082 | X30: 46112 | AA30: 46082 | AB30: 46112 | AD30: =T30-AA30 | AE30: =U30-AB30 | AF30: =V30-AC30
A31: =E31&F31 | C31: =VLOOKUP(D31,Sheet1!$A$1:$B$4,2,FALSE) | D31: ROTTERDAM | E31: ROTTERDAM | F31: LONG BEACH, CA | G31: LONG BEACH, CA | H31: =H28 | I31: =I28 | J31: =J28 | T31: =SUM(H31,K31,N31,Q31) | U31: =SUM(I31,L31,O31,R31) | V31: =SUM(J31,M31,P31,S31) | W31: 46082 | X31: 46112 | AA31: 46082 | AB31: 46112 | AD31: =T31-AA31 | AE31: =U31-AB31 | AF31: =V31-AC31
A32: =E32&F32 | C32: =VLOOKUP(D32,Sheet1!$A$1:$B$4,2,FALSE) | D32: ANTWERP | E32: ANTWERP | F32: MIAMI, FL | G32: MIAMI, FL | H32: =H26 | I32: =I26 | J32: =J26 | Q32: 37 | R32: 75 | S32: 75 | T32: =SUM(H32,K32,N32,Q32) | U32: =SUM(I32,L32,O32,R32) | V32: =SUM(J32,M32,P32,S32) | W32: 46082 | X32: 46112 | AA32: 46082 | AB32: 46112 | AD32: =T32-AA32 | AE32: =U32-AB32 | AF32: =V32-AC32
A33: =E33&F33 | C33: =VLOOKUP(D33,Sheet1!$A$1:$B$4,2,FALSE) | D33: ANTWERP | E33: ANTWERP | F33: OAKLAND, CA | G33: OAKLAND, CA | H33: =H27 | I33: =I27 | J33: =J27 | T33: =SUM(H33,K33,N33,Q33) | U33: =SUM(I33,L33,O33,R33) | V33: =SUM(J33,M33,P33,S33) | W33: 46082 | X33: 46112 | AA33: 46082 | AB33: 46112 | AD33: =T33-AA33 | AE33: =U33-AB33 | AF33: =V33-AC33
A34: =E34&F34 | C34: =VLOOKUP(D34,Sheet1!$A$1:$B$4,2,FALSE) | D34: ANTWERP | E34: ANTWERP | F34: LONG BEACH, CA | G34: LONG BEACH, CA | H34: =H28 | I34: =I28 | J34: =J28 | T34: =SUM(H34,K34,N34,Q34) | U34: =SUM(I34,L34,O34,R34) | V34: =SUM(J34,M34,P34,S34) | W34: 46082 | X34: 46112 | AA34: 46082 | AB34: 46112 | AD34: =T34-AA34 | AE34: =U34-AB34 | AF34: =V34-AC34
A35: =E35&F35 | B35: =G35&F35 | C35: =VLOOKUP(D35,Sheet1!$A$1:$B$4,2,FALSE) | D35: BREMERHAVEN | E35: BREMERHAVEN | F35: SAVANNAH, GA | G35: ATLANTA, GA | H35: =VLOOKUP($A35,$A$5:$J$34,8,FALSE) | I35: =VLOOKUP($A35,$A$5:$J$34,9,FALSE) | J35: =VLOOKUP($A35,$A$5:$J$34,10,FALSE) | K35: =VLOOKUP($B35,'US inland'!$A$7:$G$27,6,FALSE) | L35: =VLOOKUP($B35,'US inland'!$A$7:$G$27,7,FALSE) | M35: =VLOOKUP($B35,'US inland'!$A$7:$G$27,7,FALSE) | N35: =VLOOKUP($F35,$F$19:$S$34,9,FALSE) | O35: =VLOOKUP($F35,$F$19:$S$34,10,FALSE) | P35: =VLOOKUP($F35,$F$19:$S$34,11,FALSE) | Q35: =VLOOKUP($F35,$F$19:$S$34,12,FALSE) | R35: =VLOOKUP($F35,$F$19:$S$34,13,FALSE) | S35: =VLOOKUP($F35,$F$19:$S$34,14,FALSE) | T35: =SUM(H35,K35,N35,Q35) | U35: =SUM(I35,L35,O35,R35) | V35: =SUM(J35,M35,P35,S35) | W35: 46082 | X35: 46112 | AA35: 46082 | AB35: 46112 | AD35: =T35-AA35 | AE35: =U35-AB35 | AF35: =V35-AC35
A36: =E36&F36 | B36: =G36&F36 | C36: =VLOOKUP(D36,Sheet1!$A$1:$B$4,2,FALSE) | D36: BREMERHAVEN | E36: BREMERHAVEN | F36: SAVANNAH, GA | G36: CHARLOTTE, NC | H36: =VLOOKUP($A36,$A$5:$J$34,8,FALSE) | I36: =VLOOKUP($A36,$A$5:$J$34,8,FALSE) | J36: =VLOOKUP($A36,$A$5:$J$34,9,FALSE) | K36: =VLOOKUP($B36,'US inland'!$A$7:$G$27,6,FALSE) | L36: =VLOOKUP($B36,'US inland'!$A$7:$G$27,7,FALSE) | M36: =VLOOKUP($B36,'US inland'!$A$7:$G$27,7,FALSE) | N36: =VLOOKUP($F36,$F$19:$S$34,9,FALSE) | O36: =VLOOKUP($F36,$F$19:$S$34,10,FALSE) | P36: =VLOOKUP($F36,$F$19:$S$34,11,FALSE) | Q36: =VLOOKUP($F36,$F$19:$S$34,12,FALSE) | R36: =VLOOKUP($F36,$F$19:$S$34,13,FALSE) | S36: =VLOOKUP($F36,$F$19:$S$34,14,FALSE) | T36: =SUM(H36,K36,N36,Q36) | U36: =SUM(I36,L36,O36,R36) | V36: =SUM(J36,M36,P36,S36) | W36: 46082 | X36: 46112 | AA36: 46082 | AB36: 46112 | AD36: =T36-AA36 | AE36: =U36-AB36 | AF36: =V36-AC36
A37: =E37&F37 | B37: =G37&F37 | C37: =VLOOKUP(D37,Sheet1!$A$1:$B$4,2,FALSE) | D37: ROTTERDAM | E37: ROTTERDAM | F37: SAVANNAH, GA | G37: ATLANTA, GA | H37: =VLOOKUP($A37,$A$5:$J$34,8,FALSE) | I37: =VLOOKUP($A37,$A$5:$J$34,8,FALSE) | J37: =VLOOKUP($A37,$A$5:$J$34,9,FALSE) | K37: =VLOOKUP($B37,'US inland'!$A$7:$G$27,6,FALSE) | L37: =VLOOKUP($B37,'US inland'!$A$7:$G$27,7,FALSE) | M37: =VLOOKUP($B37,'US inland'!$A$7:$G$27,7,FALSE) | N37: =VLOOKUP($F37,$F$19:$S$34,9,FALSE) | O37: =VLOOKUP($F37,$F$19:$S$34,10,FALSE) | P37: =VLOOKUP($F37,$F$19:$S$34,11,FALSE) | Q37: =VLOOKUP($F37,$F$19:$S$34,12,FALSE) | R37: =VLOOKUP($F37,$F$19:$S$34,13,FALSE) | S37: =VLOOKUP($F37,$F$19:$S$34,14,FALSE) | T37: =SUM(H37,K37,N37,Q37) | U37: =SUM(I37,L37,O37,R37) | V37: =SUM(J37,M37,P37,S37) | W37: 46082 | X37: 46112 | AA37: 46082 | AB37: 46112 | AD37: =T37-AA37 | AE37: =U37-AB37 | AF37: =V37-AC37
A38: =E38&F38 | B38: =G38&F38 | C38: =VLOOKUP(D38,Sheet1!$A$1:$B$4,2,FALSE) | D38: ROTTERDAM | E38: ROTTERDAM | F38: SAVANNAH, GA | G38: CHARLOTTE, NC | H38: =VLOOKUP($A38,$A$5:$J$34,8,FALSE) | I38: =VLOOKUP($A38,$A$5:$J$34,8,FALSE) | J38: =VLOOKUP($A38,$A$5:$J$34,9,FALSE) | K38: =VLOOKUP($B38,'US inland'!$A$7:$G$27,6,FALSE) | L38: =VLOOKUP($B38,'US inland'!$A$7:$G$27,7,FALSE) | M38: =VLOOKUP($B38,'US inland'!$A$7:$G$27,7,FALSE) | N38: =VLOOKUP($F38,$F$19:$S$34,9,FALSE) | O38: =VLOOKUP($F38,$F$19:$S$34,10,FALSE) | P38: =VLOOKUP($F38,$F$19:$S$34,11,FALSE) | Q38: =VLOOKUP($F38,$F$19:$S$34,12,FALSE) | R38: =VLOOKUP($F38,$F$19:$S$34,13,FALSE) | S38: =VLOOKUP($F38,$F$19:$S$34,14,FALSE) | T38: =SUM(H38,K38,N38,Q38) | U38: =SUM(I38,L38,O38,R38) | V38: =SUM(J38,M38,P38,S38) | W38: 46082 | X38: 46112 | AA38: 46082 | AB38: 46112 | AD38: =T38-AA38 | AE38: =U38-AB38 | AF38: =V38-AC38
A39: =E39&F39 | B39: =G39&F39 | C39: =VLOOKUP(D39,Sheet1!$A$1:$B$4,2,FALSE) | D39: ANTWERP | E39: ANTWERP | F39: SAVANNAH, GA | G39: ATLANTA, GA | H39: =VLOOKUP($A39,$A$5:$J$34,8,FALSE) | I39: =VLOOKUP($A39,$A$5:$J$34,8,FALSE) | J39: =VLOOKUP($A39,$A$5:$J$34,9,FALSE) | K39: =VLOOKUP($B39,'US inland'!$A$7:$G$27,6,FALSE) | L39: =VLOOKUP($B39,'US inland'!$A$7:$G$27,7,FALSE) | M39: =VLOOKUP($B39,'US inland'!$A$7:$G$27,7,FALSE) | N39: =VLOOKUP($F39,$F$19:$S$34,9,FALSE) | O39: =VLOOKUP($F39,$F$19:$S$34,10,FALSE) | P39: =VLOOKUP($F39,$F$19:$S$34,11,FALSE) | Q39: =VLOOKUP($F39,$F$19:$S$34,12,FALSE) | R39: =VLOOKUP($F39,$F$19:$S$34,13,FALSE) | S39: =VLOOKUP($F39,$F$19:$S$34,14,FALSE) | T39: =SUM(H39,K39,N39,Q39) | U39: =SUM(I39,L39,O39,R39) | V39: =SUM(J39,M39,P39,S39) | W39: 46082 | X39: 46112 | AA39: 46082 | AB39: 46112 | AD39: =T39-AA39 | AE39: =U39-AB39 | AF39: =V39-AC39
A40: =E40&F40 | B40: =G40&F40 | C40: =VLOOKUP(D40,Sheet1!$A$1:$B$4,2,FALSE) | D40: ANTWERP | E40: ANTWERP | F40: SAVANNAH, GA | G40: CHARLOTTE, NC | H40: =VLOOKUP($A40,$A$5:$J$34,8,FALSE) | I40: =VLOOKUP($A40,$A$5:$J$34,8,FALSE) | J40: =VLOOKUP($A40,$A$5:$J$34,9,FALSE) | K40: =VLOOKUP($B40,'US inland'!$A$7:$G$27,6,FALSE) | L40: =VLOOKUP($B40,'US inland'!$A$7:$G$27,7,FALSE) | M40: =VLOOKUP($B40,'US inland'!$A$7:$G$27,7,FALSE) | N40: =VLOOKUP($F40,$F$19:$S$34,9,FALSE) | O40: =VLOOKUP($F40,$F$19:$S$34,10,FALSE) | P40: =VLOOKUP($F40,$F$19:$S$34,11,FALSE) | Q40: =VLOOKUP($F40,$F$19:$S$34,12,FALSE) | R40: =VLOOKUP($F40,$F$19:$S$34,13,FALSE) | S40: =VLOOKUP($F40,$F$19:$S$34,14,FALSE) | T40: =SUM(H40,K40,N40,Q40) | U40: =SUM(I40,L40,O40,R40) | V40: =SUM(J40,M40,P40,S40) | W40: 46082 | X40: 46112 | AA40: 46082 | AB40: 46112 | AD40: =T40-AA40 | AE40: =U40-AB40 | AF40: =V40-AC40
A41: =E41&F41 | B41: =G41&F41 | C41: =VLOOKUP(D41,Sheet1!$A$1:$B$4,2,FALSE) | D41: BREMERHAVEN | E41: BREMERHAVEN | F41: NEW YORK, NY | G41: CHICAGO, IL | H41: =VLOOKUP($A41,$A$5:$J$34,8,FALSE) | I41: =VLOOKUP($A41,$A$5:$J$34,8,FALSE) | J41: =VLOOKUP($A41,$A$5:$J$34,9,FALSE) | K41: =VLOOKUP($B41,'US inland'!$A$7:$G$27,6,FALSE) | L41: =VLOOKUP($B41,'US inland'!$A$7:$G$27,7,FALSE) | M41: =VLOOKUP($B41,'US inland'!$A$7:$G$27,7,FALSE) | N41: =VLOOKUP($F41,$F$19:$S$34,9,FALSE) | O41: =VLOOKUP($F41,$F$19:$S$34,10,FALSE) | P41: =VLOOKUP($F41,$F$19:$S$34,11,FALSE) | Q41: =VLOOKUP($F41,$F$19:$S$34,12,FALSE) | R41: =VLOOKUP($F41,$F$19:$S$34,13,FALSE) | S41: =VLOOKUP($F41,$F$19:$S$34,14,FALSE) | T41: =SUM(H41,K41,N41,Q41) | U41: =SUM(I41,L41,O41,R41) | V41: =SUM(J41,M41,P41,S41) | W41: 46082 | X41: 46112 | AA41: 46082 | AB41: 46112 | AD41: =T41-AA41 | AE41: =U41-AB41 | AF41: =V41-AC41
A42: =E42&F42 | B42: =G42&F42 | C42: =VLOOKUP(D42,Sheet1!$A$1:$B$4,2,FALSE) | D42: BREMERHAVEN | E42: BREMERHAVEN | F42: NEW YORK, NY | G42: CINCINNATI, OH | H42: =VLOOKUP($A42,$A$5:$J$34,8,FALSE) | I42: =VLOOKUP($A42,$A$5:$J$34,8,FALSE) | J42: =VLOOKUP($A42,$A$5:$J$34,9,FALSE) | K42: =VLOOKUP($B42,'US inland'!$A$7:$G$27,6,FALSE) | L42: =VLOOKUP($B42,'US inland'!$A$7:$G$27,7,FALSE) | M42: =VLOOKUP($B42,'US inland'!$A$7:$G$27,7,FALSE) | N42: =VLOOKUP($F42,$F$19:$S$34,9,FALSE) | O42: =VLOOKUP($F42,$F$19:$S$34,10,FALSE) | P42: =VLOOKUP($F42,$F$19:$S$34,11,FALSE) | Q42: =VLOOKUP($F42,$F$19:$S$34,12,FALSE) | R42: =VLOOKUP($F42,$F$19:$S$34,13,FALSE) | S42: =VLOOKUP($F42,$F$19:$S$34,14,FALSE) | T42: =SUM(H42,K42,N42,Q42) | U42: =SUM(I42,L42,O42,R42) | V42: =SUM(J42,M42,P42,S42) | W42: 46082 | X42: 46112 | AA42: 46082 | AB42: 46112 | AD42: =T42-AA42 | AE42: =U42-AB42 | AF42: =V42-AC42
...

Sheet Sheet1
A1: BREMERHAVEN | B1: GERMANY
A2: ROTTERDAM | B2: NETHERLANDS
A3: ANTWERP | B3: BELGIUM
A4: HAMBURG | B4: GERMANY

Sheet US inland
B2: US inland
B3: Validity : 10/01/2025 - 12/31/2025
B6: Location | C6: Location Type | D6: Routing via | F6: 20DV | G6: 40DV/40HQ | H6: 40RF/40RQ
A7: =B7&E7 | B7: ATLANTA, GA | C7: Ramp | D7: SAV | E7: SAVANNAH, GA | F7: 675 | G7: 700
A8: =B8&E8 | B8: CHARLOTTE, NC | C8: Rail Ramp | D8: SAV | E8: SAVANNAH, GA | F8: 700 | G8: 800
A9: =B9&E9 | B9: CHICAGO, IL | C9: Rail Ramp | D9: NYC | E9: NEW YORK, NY | F9: 750 | G9: 900 | H9: 2000
A10: =B10&E10 | B10: CINCINNATI, OH | C10: Rail Ramp | D10: NYC | E10: NEW YORK, NY | F10: 850 | G10: 1025
A11: =B11&E11 | B11: CLEVELAND, OH | C11: Rail Ramp | D11: NYC | E11: NEW YORK, NY | F11: 1050 | G11: 1150
A12: =B12&E12 | B12: COLUMBUS, OH | C12: Depot | D12: NYC | E12: NEW YORK, NY | F12: 840 | G12: 950
A13: =B13&E13 | B13: DALLAS, TX | C13: Rail Ramp / Depot | D13: SAV | E13: SAVANNAH, GA | F13: 2300 | G13: 2700
A14: =B14&E14 | B14: DENVER, CO | C14: Rail Ramp / Depot | D14: OAK | E14: OAKLAND, CA | F14: 2380 | G14: 2840
A15: =B15&E15 | B15: DETROIT, MI | C15: Rail Ramp | D15: NYC | E15: NEW YORK, NY | F15: 1050 | G15: 1200
A16: =B16&E16 | B16: GREER, SC | C16: Rail Ramp | D16: CHS | E16: CHARLESTON, SC | F16: 1060 | G16: 1140
A17: =B17&E17 | B17: INDIANAPOLIS, IN | C17: Depot | D17: NYC | E17: NEW YORK, NY | F17: 1260 | G17: 1440
A18: =B18&E18 | B18: KANSAS CITY, MO | C18: Depot | D18: NYC | E18: NEW YORK, NY | F18: 1150 | G18: 1400
A19: =B19&E19 | B19: LONG BEACH, CA | C19: Rail Ramp | D19: HOU | E19: HOUSTON, TX | F19: 1870 | G19: 2250
A20: =B20&E20 | B20: LOUISVILLE, KY | C20: Rail Ramp | D20: ORF | E20: NORFOLK, VA | F20: 975 | G20: 1300
A21: =B21&E21 | B21: MEMPHIS, TN | C21: Rail Ramp | D21: SAV | E21: SAVANNAH, GA | F21: 860 | G21: 990
... A27: =B27&E27 | B27: TAMPA, FL | C27: Rail Ramp / Depot | D27: SAV | E27: SAVANNAH, GA | F27: 1050 | G27: 1150
B33: SAV | C33: SAVANNAH, GA
B34: NYC | C34: NEW YORK, NY
B35: OAK | C35: OAKLAND, CA
B36: CHS | C36: CHARLESTON, SC
B37: HOU | C37: HOUSTON, TX
B38: ORF | C38: NORFOLK, VA
